Workbook
Name курс: Auto_Delivery_CN!$K$1
Name AutoCityList: Auto_Delivery_CN!$A$3:$A$57

Sheet Quote_Calculator
A1: Калькулятор маршрута / 路线报价: Город X → Suzhou Jiangsu / 江苏苏州 → Москва / 莫斯科
A2: Входные данные | D2: Итог для клиента
A3: Город отправления / 起运城市 | B3: Shanghai / 上海 | D3: Маршрут / 路线 | E3: =IF(B12="Да",B13&" → Suzhou Jiangsu → Москва",B3&" → Suzhou Jiangsu → Москва") -> Dongguan / 东莞 → Suzhou Jiangsu → Москва
A4: Назначение / 目的地 | B4: Москва / 莫斯科 | D4: Расчетный объем к тарифу, м³ / 计费体积 | E4: =MAX(B6/Controls!$B$6,IF(B8="Да",B5,B9)) -> 8.08
A5: Фактический объем, м³ / 实际体积 | B5: 5 | D5: Объемный вес, кг / 计费重量 | E5: =E4*Controls!$B$6 -> 4040
A6: Вес брутто, кг / 毛重 | B6: 4040 | D6: Диапазон объема / 体积区间 | E6: =IF(E4<=1,"0-1",IF(E4<=5,"1-5",IF(E4<=10,"5-10",">10"))) -> 5-10
A7: Паллетизирован? / 是否打托 | B7: Да | D7: Тарифное ЖД плечо, USD / 铁路费用 | E7: =IF(E6="0-1",Controls!$B$9,IF(E6="1-5",E4*Controls!$B$10,IF(E6="5-10",E4*Controls!$B$11,E4*Controls!$B$12))) -> 1212
A8: Штабелируемый груз? / 可否堆叠 | B8: Да | D8: Сбор за документы, USD / 文件费 | E8: =Controls!$B$8 -> 150
A9: Объем к оплате, м³ / 计费体积 | B9: 3 | D9: Авто: расчет за м³, USD / 提货按方 | E9: =IF(B12="Да",E4*IFERROR(VLOOKUP(B13,Auto_Delivery_CN!$A$3:$I$200,3,FALSE()),0),0) -> 140.52174
A10: Вес одного места, кг / 单件重量 | B10: 2000 | D10: Авто: расчет за тонну, USD / 提货按吨 | E10: =IF(B12="Да",(B6/1000)*IFERROR(VLOOKUP(B13,Auto_Delivery_CN!$A$3:$I$200,4,FALSE()),0),0) -> 263.47826
A11: Длина места, м / 单件长度 | B11: 5 | D11: Авто: база, USD / 提货基础价 | E11: =MAX(E9,E10) -> 263.47826
A12: Нужна автодоставка? / 是否提货 | B12: Да | D12: Комиссия агента, USD / 代理费 | E12: =IF(B12="Да",Controls!$B$17/курс,0) -> 0
A13: Город автодоставки / 提货城市 | B13: Dongguan / 东莞 | D13: Pickup charge, USD / 提货附加费 | E13: =IF(B12="Да",IF(OR(E4>=15,B6/1000>=4),Controls!$B$19/курс,Controls!$B$18/курс),0) -> 50.724638
D14: Автодоставка итого, USD / 提货合计 | E14: =SUM(E11:E13) -> 314.2029
D15: Итоговая стоимость, USD / 总价 | E15: =E7+E8+E14 -> 1676.2029
D16: Стоимость за м³, USD | E16: =IF(E4>0,E15/E4,"") -> 207.45085
D17: Контейнерный ориентир, USD/м³ | E17: =Controls!$B$5 -> 140.84507
D18: Контейнерный эквивалент, USD | E18: =E4*Controls!$B$5 -> 1138.0282
D19: Премия к контейнерному ориентиру | E19: =IF(E18>0,E15/E18-1,"") -> 0.47290106
D20: Доля авто в ЖД | E20: =IF(E7>0,E14/E7,0) -> 0.25924332
D21: Проверка ограничений | E21: =IF(B10>Controls!$B$15,"вес места > 3 т","")&IF(AND(B10>Controls!$B$15,B11>Controls!$B$16),"; ","")&IF(B11>Controls!$B$16,"длина > 6 м","")&IF(AND(B8="Нет",B9<B5,OR(B10>Controls!$B$15,B11>Controls!$B$16)),"; ","")&IF(AND(B8="Нет",B9<B5),"проверьте объем к оплате","")
D22: Статус маршрута | E22: =IF(OR(B10>Controls!$B$15,B11>Controls!$B$16),"Требует согласования",IF(AND(B12="Да",COUNTIF(Auto_Delivery_CN!$A$3:$A$200,B13)=0),"Нет ставки авто",IF(AND(B12="Да",OR(E20>Controls!$B$14,E19>Controls!$B$13-1)),"Проверить вручную","Ок"))) -> Проверить вручную

Sheet Controls
A1: Модель и ограничения
A2: Параметр | B2: Значение | C2: Ед. | D2: Комментарий
A3: Стоимость целого контейнера | B3: 10000 | C3: USD | D3: Исходная стоимость контейнера
A4: Вместимость контейнера | B4: 71 | C4: м³ | D4: Редактируемое допущение
A5: Контейнерный ориентир | B5: =B3/B4 -> 140.84507 | C5: USD/м³ | D5: Стоимость контейнера / вместимость
A6: Объемный коэффициент | B6: 500 | C6: кг/м³ | D6: Для ЖД плеча: 1 м³ = 500 кг
A7: Авто-доставка: 1 м³ = | B7: 1 | C7: т | D7: Для сравнения ставок за м³ и за тонну
A8: Сбор за документы | B8: 150 | C8: USD/партия | D8: Добавляется всегда
A9: Тариф 0–1 м³ (фикс.) | B9: 150 | C9: USD | D9: Фиксированная ставка
A10: Тариф 1–5 м³ | B10: 150 | C10: USD/м³ | D10: Ставка за куб
A11: Тариф 5–10 м³ | B11: 150 | C11: USD/м³ | D11: Ставка за куб
A12: Тариф >10 м³ | B12: 150 | C12: USD/м³ | D12: Ставка за куб
A13: Допустимая премия к контейнерному ориентиру | B13: 1.25 | C13: x | D13: Для полной ставки
A14: Макс. доля авто к ЖД плечу | B14: 0.35 | C14: доля | D14: Если выше — проверить вручную
A15: Макс. вес одного места | B15: 3000 | C15: кг | D15: Ограничение
A16: Макс. длина одного места | B16: 6 | C16: м | D16: Ограничение
A17: Комиссия агента (авто) | B17: 0 | C17: CNY/партия | D17: Добавляется к каждой партии при автодоставке
... A19: Pickup charge ≥ 15 м³ или ≥ 4 т | B19: 350 | C19: CNY/партия | D19: Сбор за партию, если объем ≥ 15 м³ или вес ≥ 4 т
G24: 5

Sheet Auto_Delivery_CN
A1: Автодоставка до станции Suzhou Jiangsu / 提货到江苏苏州站 | I1: курс | J1: = | K1: 6.9
A2: Город отправления / 提货城市 | B2: Станция хаба / 集货站 | C2: Ставка, USD/м³ | D2: Ставка, USD/т | E2: Комиссия агента, USD/партия | F2: Pickup charge <15м³/<4т, USD/партия | G2: Pickup charge ≥15м³/≥4т, USD/партия | H2: Активна / 启用 | I2: Примечание / 备注 | J2: City_EN | K2: City_CN
A3: Beijing / 北京 | B3: Suzhou Jiangsu / 江苏苏州 | C3: =O3/курс -> 14.492754 | D3: =N3/курс -> 57.971014 | E3: =Controls!$B$17/курс -> 0 | F3: =Controls!$B$18/курс -> 36.231884 | G3: =Controls!$B$19/курс -> 50.724638 | H3: Да | I3: Авто = MAX(м³×USD/м³; т×USD/т) + комиссия агента + pickup charge | J3: Beijing | K3: 北京 | M3: Beijing | N3: 400 | O3: 100 | Q3: 0
A4: Tianjin / 天津 | B4: Suzhou Jiangsu / 江苏苏州 | C4: =O4/курс -> 14.492754 | D4: =N4/курс -> 57.971014 | E4: =Controls!$B$17/курс -> 0 | F4: =Controls!$B$18/курс -> 36.231884 | G4: =Controls!$B$19/курс -> 50.724638 | H4: Да | I4: Авто = MAX(м³×USD/м³; т×USD/т) + комиссия агента + pickup charge | J4: Tianjin | K4: 天津 | M4: Tianjin | N4: 400 | O4: 100 | Q4: 0
A5: Shanghai / 上海 | B5: Suzhou Jiangsu / 江苏苏州 | C5: =O5/курс -> 8.6956522 | D5: =N5/курс -> 26.086957 | E5: =Controls!$B$17/курс -> 0 | F5: =Controls!$B$18/курс -> 36.231884 | G5: =Controls!$B$19/курс -> 50.724638 | H5: Да | I5: Авто = MAX(м³×USD/м³; т×USD/т) + комиссия агента + pickup charge | J5: Shanghai | K5: 上海 | M5: Shanghai | N5: 180 | O5: 60 | Q5: 0
A6: Chongqing / 重庆 | B6: Suzhou Jiangsu / 江苏苏州 | C6: =O6/курс -> 17.391304 | D6: =N6/курс -> 72.463768 | E6: =Controls!$B$17/курс -> 0 | F6: =Controls!$B$18/курс -> 36.231884 | G6: =Controls!$B$19/курс -> 50.724638 | H6: Да | I6: Авто = MAX(м³×USD/м³; т×USD/т) + комиссия агента + pickup charge | J6: Chongqing | K6: 重庆 | M6: Chongqing | N6: 500 | O6: 120 | Q6: 0
A7: Shenyang / 沈阳 | B7: Suzhou Jiangsu / 江苏苏州 | C7: =O7/курс -> 21.73913 | D7: =N7/курс -> 79.710145 | E7: =Controls!$B$17/курс -> 0 | F7: =Controls!$B$18/курс -> 36.231884 | G7: =Controls!$B$19/курс -> 50.724638 | H7: Да | I7: Авто = MAX(м³×USD/м³; т×USD/т) + комиссия агента + pickup charge | J7: Shenyang | K7: 沈阳 | M7: Shenyang | N7: 550 | O7: 150 | Q7: 0
A8: Dalian / 大连 | B8: Suzhou Jiangsu / 江苏苏州 | C8: =O8/курс -> 26.086957 | D8: =N8/курс -> 94.202899 | E8: =Controls!$B$17/курс -> 0 | F8: =Controls!$B$18/курс -> 36.231884 | G8: =Controls!$B$19/курс -> 50.724638 | H8: Да | I8: Авто = MAX(м³×USD/м³; т×USD/т) + комиссия агента + pickup charge | J8: Dalian | K8: 大连 | M8: Dalian | N8: 650 | O8: 180 | Q8: 0
A9: Shijiazhuang / 石家庄 | B9: Suzhou Jiangsu / 江苏苏州 | C9: =O9/курс -> 14.492754 | D9: =N9/курс -> 55.072464 | E9: =Controls!$B$17/курс -> 0 | F9: =Controls!$B$18/курс -> 36.231884 | G9: =Controls!$B$19/курс -> 50.724638 | H9: Да | I9: Авто = MAX(м³×USD/м³; т×USD/т) + комиссия агента + pickup charge | J9: Shijiazhuang | K9: 石家庄 | M9: Shijiazhuang | N9: 380 | O9: 100 | Q9: 0
A10: Cangzhou / 沧州 | B10: Suzhou Jiangsu / 江苏苏州 | C10: =O10/курс -> 14.492754 | D10: =N10/курс -> 55.072464 | E10: =Controls!$B$17/курс -> 0 | F10: =Controls!$B$18/курс -> 36.231884 | G10: =Controls!$B$19/курс -> 50.724638 | H10: Да | I10: Авто = MAX(м³×USD/м³; т×USD/т) + комиссия агента + pickup charge | J10: Cangzhou | K10: 沧州 | M10: Cangzhou | N10: 380 | O10: 100 | Q10: 0
A11: Baoding / 保定 | B11: Suzhou Jiangsu / 江苏苏州 | C11: =O11/курс -> 14.492754 | D11: =N11/курс -> 55.072464 | E11: =Controls!$B$17/курс -> 0 | F11: =Controls!$B$18/курс -> 36.231884 | G11: =Controls!$B$19/курс -> 50.724638 | H11: Да | I11: Авто = MAX(м³×USD/м³; т×USD/т) + комиссия агента + pickup charge | J11: Baoding | K11: 保定 | M11: Baoding | N11: 380 | O11: 100 | Q11: 0
A12: Xingtai / 邢台 | B12: Suzhou Jiangsu / 江苏苏州 | C12: =O12/курс -> 14.492754 | D12: =N12/курс -> 55.072464 | E12: =Controls!$B$17/курс -> 0 | F12: =Controls!$B$18/курс -> 36.231884 | G12: =Controls!$B$19/курс -> 50.724638 | H12: Да | I12: Авто = MAX(м³×USD/м³; т×USD/т) + комиссия агента + pickup charge | J12: Xingtai | K12: 邢台 | M12: Xingtai | N12: 380 | O12: 100 | Q12: 0
A13: Hengshui / 衡水 | B13: Suzhou Jiangsu / 江苏苏州 | C13: =O13/курс -> 14.492754 | D13: =N13/курс -> 50.724638 | E13: =Controls!$B$17/курс -> 0 | F13: =Controls!$B$18/курс -> 36.231884 | G13: =Controls!$B$19/курс -> 50.724638 | H13: Да | I13: Авто = MAX(м³×USD/м³; т×USD/т) + комиссия агента + pickup charge | J13: Hengshui | K13: 衡水 | M13: Hengshui | N13: 350 | O13: 100 | Q13: 0
A14: Jinan / 济南 | B14: Suzhou Jiangsu / 江苏苏州 | C14: =O14/курс -> 14.492754 | D14: =N14/курс -> 43.478261 | E14: =Controls!$B$17/курс -> 0 | F14: =Controls!$B$18/курс -> 36.231884 | G14: =Controls!$B$19/курс -> 50.724638 | H14: Да | I14: Авто = MAX(м³×USD/м³; т×USD/т) + комиссия агента + pickup charge | J14: Jinan | K14: 济南 | M14: Jinan | N14: 300 | O14: 100 | Q14: 0
... A18: Weifang / 潍坊 | B18: Suzhou Jiangsu / 江苏苏州 | C18: =O18/курс -> 14.492754 | D18: =N18/курс -> 43.478261 | E18: =Controls!$B$17/курс -> 0 | F18: =Controls!$B$18/курс -> 36.231884 | G18: =Controls!$B$19/курс -> 50.724638 | H18: Да | I18: Авто = MAX(м³×USD/м³; т×USD/т) + комиссия агента + pickup charge | J18: Weifang | K18: 潍坊 | M18: Weifang | N18: 300 | O18: 100 | Q18: 0
A19: Jining | B19: Suzhou Jiangsu / 江苏苏州 | C19: =O19/курс -> 14.492754 | D19: =N19/курс -> 43.478261 | E19: =Controls!$B$17/курс -> 0 | F19: =Controls!$B$18/курс -> 36.231884 | G19: =Controls!$B$19/курс -> 50.724638 | H19: Да | I19: Авто = MAX(м³×USD/м³; т×USD/т) + комиссия агента + pickup charge | J19: Jining | M19: Jining | N19: 300 | O19: 100 | Q19: 0
A20: Dezhou | B20: Suzhou Jiangsu / 江苏苏州 | C20: =O20/курс -> 14.492754 | D20: =N20/курс -> 43.478261 | E20: =Controls!$B$17/курс -> 0 | F20: =Controls!$B$18/курс -> 36.231884 | G20: =Controls!$B$19/курс -> 50.724638 | H20: Да | I20: Авто = MAX(м³×USD/м³; т×USD/т) + комиссия агента + pickup charge | J20: Dezhou | M20: Dezhou | N20: 300 | O20: 100 | Q20: 0
A21: Linyi / 临沂 | B21: Suzhou Jiangsu / 江苏苏州 | C21: =O21/курс -> 10.869565 | D21: =N21/курс -> 36.231884 | E21: =Controls!$B$17/курс -> 0 | F21: =Controls!$B$18/курс -> 36.231884 | G21: =Controls!$B$19/курс -> 50.724638 | H21: Да | I21: Авто = MAX(м³×USD/м³; т×USD/т) + комиссия агента + pickup charge | J21: Linyi | K21: 临沂 | M21: Linyi | N21: 250 | O21: 75 | Q21: 0
A22: Nanjing / 南京 | B22: Suzhou Jiangsu / 江苏苏州 | C22: =O22/курс -> 7.2463768 | D22: =N22/курс -> 21.73913 | E22: =Controls!$B$17/курс -> 0 | F22: =Controls!$B$18/курс -> 36.231884 | G22: =Controls!$B$19/курс -> 50.724638 | H22: Да | I22: Авто = MAX(м³×USD/м³; т×USD/т) + комиссия агента + pickup charge | J22: Nanjing | K22: 南京 | M22: Nanjing | N22: 150 | O22: 50 | Q22: 0
A23: Wuxi / 无锡 | B23: Suzhou Jiangsu / 江苏苏州 | C23: =O23/курс -> 7.2463768 | D23: =N23/курс -> 21.73913 | E23: =Controls!$B$17/курс -> 0 | F23: =Controls!$B$18/курс -> 36.231884 | G23: =Controls!$B$19/курс -> 50.724638 | H23: Да | I23: Авто = MAX(м³×USD/м³; т×USD/т) + комиссия агента + pickup charge | J23: Wuxi | K23: 无锡 | M23: Wuxi | N23: 150 | O23: 50 | Q23: 0
A24: Changzhou | B24: Suzhou Jiangsu / 江苏苏州 | C24: =O24/курс -> 7.2463768 | D24: =N24/курс -> 21.73913 | E24: =Controls!$B$17/курс -> 0 | F24: =Controls!$B$18/курс -> 36.231884 | G24: =Controls!$B$19/курс -> 50.724638 | H24: Да | I24: Авто = MAX(м³×USD/м³; т×USD/т) + комиссия агента + pickup charge | J24: Changzhou | M24: Changzhou | N24: 150 | O24: 50 | Q24: 0
A25: Suzhou / 苏州 | B25: Suzhou Jiangsu / 江苏苏州 | C25: =O25/курс -> 5.7971014 | D25: =N25/курс -> 11.594203 | E25: =Controls!$B$17/курс -> 0 | F25: =Controls!$B$18/курс -> 36.231884 | G25: =Controls!$B$19/курс -> 50.724638 | H25: Да | I25: Авто = MAX(м³×USD/м³; т×USD/т) + комиссия агента + pickup charge | J25: Suzhou | K25: 苏州 | M25: Suzhou | N25: 80 | O25: 40 | Q25: 0
A26: Kunshan | B26: Suzhou Jiangsu / 江苏苏州 | C26: =O26/курс -> 7.2463768 | D26: =N26/курс -> 14.492754 | E26: =Controls!$B$17/курс -> 0 | F26: =Controls!$B$18/курс -> 36.231884 | G26: =Controls!$B$19/курс -> 50.724638 | H26: Да | I26: Авто = MAX(м³×USD/м³; т×USD/т) + комиссия агента + pickup charge | J26: Kunshan | M26: Kunshan | N26: 100 | O26: 50 | Q26: 0
A27: Taicang | B27: Suzhou Jiangsu / 江苏苏州 | C27: =O27/курс -> 7.2463768 | D27: =N27/курс -> 21.73913 | E27: =Controls!$B$17/курс -> 0 | F27: =Controls!$B$18/курс -> 36.231884 | G27: =Controls!$B$19/курс -> 50.724638 | H27: Да | I27: Авто = MAX(м³×USD/м³; т×USD/т) + комиссия агента + pickup charge | J27: Taicang | M27: Taicang | N27: 150 | O27: 50 | Q27: 0
A28: Nantong | B28: Suzhou Jiangsu / 江苏苏州 | C28: =O28/курс -> 7.2463768 | D28: =N28/курс -> 21.73913 | E28: =Controls!$B$17/курс -> 0 | F28: =Controls!$B$18/курс -> 36.231884 | G28: =Controls!$B$19/курс -> 50.724638 | H28: Да | I28: Авто = MAX(м³×USD/м³; т×USD/т) + комиссия агента + pickup charge | J28: Nantong | M28: Nantong | N28: 150 | O28: 50 | Q28: 0
A29: Yancheng | B29: Suzhou Jiangsu / 江苏苏州 | C29: =O29/курс -> 8.6956522 | D29: =N29/курс -> 26.086957 | E29: =Controls!$B$17/курс -> 0 | F29: =Controls!$B$18/курс -> 36.231884 | G29: =Controls!$B$19/курс -> 50.724638 | H29: Да | I29: Авто = MAX(м³×USD/м³; т×USD/т) + комиссия агента + pickup charge | J29: Yancheng | M29: Yancheng | N29: 180 | O29: 60 | Q29: 0
A30: Yangzhou | B30: Suzhou Jiangsu / 江苏苏州 | C30: =O30/курс -> 8.6956522 | D30: =N30/курс -> 26.086957 | E30: =Controls!$B$17/курс -> 0 | F30: =Controls!$B$18/курс -> 36.231884 | G30: =Controls!$B$19/курс -> 50.724638 | H30: Да | I30: Авто = MAX(м³×USD/м³; т×USD/т) + комиссия агента + pickup charge | J30: Yangzhou | M30: Yangzhou | N30: 180 | O30: 60 | Q30: 0
A31: Taizhou / 台州 | B31: Suzhou Jiangsu / 江苏苏州 | C31: =O31/курс -> 8.6956522 | D31: =N31/курс -> 26.086957 | E31: =Controls!$B$17/курс -> 0 | F31: =Controls!$B$18/курс -> 36.231884 | G31: =Controls!$B$19/курс -> 50.724638 | H31: Да | I31: Авто = MAX(м³×USD/м³; т×USD/т) + комиссия агента + pickup charge | J31: Taizhou | K31: 台州 | M31: Taizhou | N31: 180 | O31: 60 | Q31: 0
A32: Xuzhou | B32: Suzhou Jiangsu / 江苏苏州 | C32: =O32/курс -> 10.144928 | D32: =N32/курс -> 36.231884 | E32: =Controls!$B$17/курс -> 0 | F32: =Controls!$B$18/курс -> 36.231884 | G32: =Controls!$B$19/курс -> 50.724638 | H32: Да | I32: Авто = MAX(м³×USD/м³; т×USD/т) + комиссия агента + pickup charge | J32: Xuzhou | M32: Xuzhou | N32: 250 | O32: 70 | Q32: 0
A33: Hangzhou / 杭州 | B33: Suzhou Jiangsu / 江苏苏州 | C33: =O33/курс -> 8.6956522 | D33: =N33/курс -> 26.086957 | E33: =Controls!$B$17/курс -> 0 | F33: =Controls!$B$18/курс -> 36.231884 | G33: =Controls!$B$19/курс -> 50.724638 | H33: Да | I33: Авто = MAX(м³×USD/м³; т×USD/т) + комиссия агента + pickup charge | J33: Hangzhou | K33: 杭州 | M33: Hangzhou | N33: 180 | O33: 60 | Q33: 0
A34: Ningbo / 宁波 | B34: Suzhou Jiangsu / 江苏苏州 | C34: =O34/курс -> 8.6956522 | D34: =N34/курс -> 26.086957 | E34: =Controls!$B$17/курс -> 0 | F34: =Controls!$B$18/курс -> 36.231884 | G34: =Controls!$B$19/курс -> 50.724638 | H34: Да | I34: Авто = MAX(м³×USD/м³; т×USD/т) + комиссия агента + pickup charge | J34: Ningbo | K34: 宁波 | M34: Ningbo | N34: 180 | O34: 60 | Q34: 0
A35: Taizhou / 台州 | B35: Suzhou Jiangsu / 江苏苏州 | C35: =O35/курс -> 11.594203 | D35: =N35/курс -> 36.231884 | E35: =Controls!$B$17/курс -> 0 | F35: =Controls!$B$18/курс -> 36.231884 | G35: =Controls!$B$19/курс -> 50.724638 | H35: Да | I35: Авто = MAX(м³×USD/м³; т×USD/т) + комиссия агента + pickup charge | J35: Taizhou | K35: 台州 | M35: Taizhou | N35: 250 | O35: 80 | Q35: 0
A36: Jiaxing / 嘉兴 | B36: Suzhou Jiangsu / 江苏苏州 | C36: =O36/курс -> 8.6956522 | D36: =N36/курс -> 26.086957 | E36: =Controls!$B$17/курс -> 0 | F36: =Controls!$B$18/курс -> 36.231884 | G36: =Controls!$B$19/курс -> 50.724638 | H36: Да | I36: Авто = MAX(м³×USD/м³; т×USD/т) + комиссия агента + pickup charge | J36: Jiaxing | K36: 嘉兴 | M36: Jiaxing | N36: 180 | O36: 60 | Q36: 0
A37: Quzhou | B37: Suzhou Jiangsu / 江苏苏州 | C37: =O37/курс -> 14.492754 | D37: =N37/курс -> 50.724638 | E37: =Controls!$B$17/курс -> 0 | F37: =Controls!$B$18/курс -> 36.231884 | G37: =Controls!$B$19/курс -> 50.724638 | H37: Да | I37: Авто = MAX(м³×USD/м³; т×USD/т) + комиссия агента + pickup charge | J37: Quzhou | M37: Quzhou | N37: 350 | O37: 100 | Q37: 0
A38: Fuzhou / 福州 | B38: Suzhou Jiangsu / 江苏苏州 | C38: =O38/курс -> 14.492754 | D38: =N38/курс -> 50.724638 | E38: =Controls!$B$17/курс -> 0 | F38: =Controls!$B$18/курс -> 36.231884 | G38: =Controls!$B$19/курс -> 50.724638 | H38: Да | I38: Авто = MAX(м³×USD/м³; т×USD/т) + комиссия агента + pickup charge | J38: Fuzhou | K38: 福州 | M38: Fuzhou | N38: 350 | O38: 100 | Q38: 0
A39: Quanzhou / 泉州 | B39: Suzhou Jiangsu / 江苏苏州 | C39: =O39/курс -> 15.942029 | D39: =N39/курс -> 57.971014 | E39: =Controls!$B$17/курс -> 0 | F39: =Controls!$B$18/курс -> 36.231884 | G39: =Controls!$B$19/курс -> 50.724638 | H39: Да | I39: Авто = MAX(м³×USD/м³; т×USD/т) + комиссия агента + pickup charge | J39: Quanzhou | K39: 泉州 | M39: Quanzhou | N39: 400 | O39: 110 | Q39: 0
A40: Xiamen / 厦门 | B40: Suzhou Jiangsu / 江苏苏州 | C40: =O40/курс -> 15.942029 | D40: =N40/курс -> 57.971014 | E40: =Controls!$B$17/курс -> 0 | F40: =Controls!$B$18/курс -> 36.231884 | G40: =Controls!$B$19/курс -> 50.724638 | H40: Да | I40: Авто = MAX(м³×USD/м³; т×USD/т) + комиссия агента + pickup charge | J40: Xiamen | K40: 厦门 | M40: Xiamen | N40: 400 | O40: 110 | Q40: 0
A41: Zhangzhou / 漳州 | B41: Suzhou Jiangsu / 江苏苏州 | C41: =O41/курс -> 15.942029 | D41: =N41/курс -> 57.971014 | E41: =Controls!$B$17/курс -> 0 | F41: =Controls!$B$18/курс -> 36.231884 | G41: =Controls!$B$19/курс -> 50.724638 | H41: Да | I41: Авто = MAX(м³×USD/м³; т×USD/т) + комиссия агента + pickup charge | J41: Zhangzhou | K41: 漳州 | M41: Zhangzhou | N41: 400 | O41: 110 | Q41: 0
A42: Guangzhou / 广州 | B42: Suzhou Jiangsu / 江苏苏州 | C42: =O42/курс -> 17.391304 | D42: =N42/курс -> 65.217391 | E42: =Controls!$B$17/курс -> 0 | F42: =Controls!$B$18/курс -> 36.231884 | G42: =Controls!$B$19/курс -> 50.724638 | H42: Да | I42: Авто = MAX(м³×USD/м³; т×USD/т) + комиссия агента + pickup charge | J42: Guangzhou | K42: 广州 | M42: Guangzhou | N42: 450 | O42: 120 | Q42: 0
A43: Shenzhen / 深圳 | B43: Suzhou Jiangsu / 江苏苏州 | C43: =O43/курс -> 17.391304 | D43: =N43/курс -> 65.217391 | E43: =Controls!$B$17/курс -> 0 | F43: =Controls!$B$18/курс -> 36.231884 | G43: =Controls!$B$19/курс -> 50.724638 | H43: Да | I43: Авто = MAX(м³×USD/м³; т×USD/т) + комиссия агента + pickup charge | J43: Shenzhen | K43: 深圳 | M43: Shenzhen | N43: 450 | O43: 120 | Q43: 0
...

Sheet Test_Examples
A1: Тестовые примеры для проверки менеджером
A2: Сценарий | B2: Город | C2: Объем факт, м³ | D2: Вес, кг | E2: Штаб.? | F2: Объем к оплате, м³ | G2: Вес места, кг | H2: Длина, м | I2: Авто? | J2: Город авто | K2: Ожидаемый итог, USD | L2: Комментарий
A3: Штабел., без авто, 0.8 м³ | B3: Shanghai | C3: 0.8 | D3: 400 | E3: Да | F3: 0.8 | G3: 400 | H3: 1.2 | I3: Нет | K3: =Controls!$B$9+Controls!$B$8 -> 300 | L3: 145 + 150
A4: Не штабел., 2 м³ факт / 3 м³ к оплате | B4: Shanghai | C4: 2 | D4: 800 | E4: Нет | F4: 3 | G4: 800 | H4: 1.5 | I4: Нет | K4: =3*Controls!$B$10+Controls!$B$8 -> 600 | L4: 145×3 + 150
A5: С авто: берем больше из м³/т | B5: Shanghai | C5: 3 | D5: 2200 | E5: Да | F5: 3 | G5: 1200 | H5: 2 | I5: Да | J5: Shanghai | K5: =3*Controls!$B$10+Controls!$B$8+MAX(3*VLOOKUP("Shanghai",Auto_Delivery_CN!$A$3:$I$200,3,FALSE()),(2200/1000)*VLOOKUP("Shanghai",Auto_Delivery_CN!$A$3:$I$200,4,FALSE()))+VLOOKUP("Shanghai",Auto_Delivery_CN!$A$3:$I$200,5,FALSE())+VLOOKUP("Shanghai",Auto_Delivery_CN!$A$3:$I$200,6,FALSE()) -> #N/A | L5: база авто + 200 CNY + 250 CNY (партия <15м³ и <4т)
A6: Перевес одного места | B6: Ningbo | C6: 7 | D6: 2500 | E6: Да | F6: 7 | G6: 3500 | H6: 2.5 | I6: Да | J6: Ningbo | K6: =7*Controls!$B$11+Controls!$B$8+MAX(7*VLOOKUP("Ningbo",Auto_Delivery_CN!$A$3:$I$200,3,FALSE()),(2500/1000)*VLOOKUP("Ningbo",Auto_Delivery_CN!$A$3:$I$200,4,FALSE()))+VLOOKUP("Ningbo",Auto_Delivery_CN!$A$3:$I$200,5,FALSE())+VLOOKUP("Ningbo",Auto_Delivery_CN!$A$3:$I$200,6,FALSE()) -> #N/A | L6: должен дать статус согласования
A7: Длина > 6 м | B7: Wuxi | C7: 12 | D7: 5000 | E7: Да | F7: 12 | G7: 2500 | H7: 6.5 | I7: Нет | K7: =12*Controls!$B$12+Controls!$B$8 -> 1950 | L7: должен дать статус согласования
A8: С авто: pickup 350 CNY | B8: Shanghai | C8: 16 | D8: 4200 | E8: Да | F8: 16 | G8: 2000 | H8: 2 | I8: Да | J8: Shanghai | K8: =16*Controls!$B$12+Controls!$B$8+MAX(16*VLOOKUP("Shanghai",Auto_Delivery_CN!$A$3:$I$200,3,FALSE()),(4200/1000)*VLOOKUP("Shanghai",Auto_Delivery_CN!$A$3:$I$200,4,FALSE()))+VLOOKUP("Shanghai",Auto_Delivery_CN!$A$3:$I$200,5,FALSE())+VLOOKUP("Shanghai",Auto_Delivery_CN!$A$3:$I$200,7,FALSE()) -> #N/A | L8: база авто + 200 CNY + 350 CNY (≥15м³ или ≥4т)

Sheet README
A1: Как использовать файл / 使用说明
A2: 1. Quote_Calculator | B2: Вводите фактический объем, вес, штабелируемость, вес одного места, длину места и необходимость авто.
A3: 2. Штабелируемость | B3: Если груз не штабелируется, расчет идет по объему к оплате, который включает пустое пространство над грузом.
A4: 3. Ограничения | B4: Если вес одного места > 3 т или длина > 6 м, маршрут помечается как "Требует согласования".
A5: 4. Автодоставка | B5: На листе Auto_Delivery_CN ставка задается отдельно в USD/м³ и USD/т; в расчете берется большее из двух значений.
A6: 5. Контейнерный ориентир | B6: Рассчитывается как 7800 USD / вместимость контейнера. По умолчанию: 7800 / 68 = 114.71 USD/м³.
A7: 6. Город авто | B7: На Quote_Calculator можно выбрать город автодоставки из списка Auto_Delivery_CN, ставка пересчитается автоматически.
A9: Обновление логики автодоставки
A10: К авто на каждую партию добавляется комиссия агента 200 CNY.
A11: Pickup charge: 250 CNY за партию при объеме < 15 м³ и весе < 4 т; 350 CNY за партию при объеме ≥ 15 м³ или весе ≥ 4 т.
A12: Итог авто = MAX(объем×ставка USD/м³; вес_т×ставка USD/т) + комиссия агента + pickup charge.
A13: Исправление: расчетный объем теперь = MAX(вес/500; факт. объем для штабелируемого; объем к оплате для не штабелируемого).
A14: 7. Китайские названия / 中文 | B14: Города в авто-доставке показаны в формате English / 中文, например Shanghai / 上海.
A15: 8. Заказ из Telegram / Telegram 下单 | B15: После расчета бот показывает кнопку «Заказать». Затем клиент вводит имя и e-mail, и расчет отправляется на sales@gfeng.ru.
A16: 9. Работа 24/7 / 24小时运行 | B16: Для круглосуточной работы используйте Railway/Render/PythonAnywhere и переменные окружения из README в пакете.
